<?xml version='1.0' encoding='utf-8'?>
<robot name="go2_description">
  <link name="base">
    <!--inertial>
      <origin xyz="0.021112 0 -0.005366" rpy="0 0 0" />
      <mass value="6.921" />
      <inertia ixx="0.02448" ixy="0.00012166" ixz="0.0014849" iyy="0.098077" iyz="-3.12E-05" izz="0.107" />
    </inertial-->
    <inertial>
      <origin xyz="0.021112 0 -0.005366" rpy="0 0 0" />
      <mass value="14.140726" />
      <inertia
        ixx="0.271614"
        ixy="-0.002090"
        ixz="0.000622"
        iyy="0.293116"
        iyz="-0.008975"
        izz="0.431329" />
    </inertial>
    <visual>
      <origin xyz="0 0 0" rpy="0 0 0" />
      <geometry>
        <mesh filename="package://go2_description/meshes/base.dae" />
      </geometry>
      <material name="深色橡胶_001-effect"><color rgba="0.6717055 0.6924257 0.7742702 1" /></material><material name="白色logo_001-effect"><color rgba="1 1 1 1" /></material><material name="黑色贴纸_007-effect"><color rgba="0.009018 0.009018 0.009018 1" /></material><material name="黑色金属_007-effect"><color rgba="0.01341 0.01341 0.01341 1" /></material><material name="黑色塑料_003-effect"><color rgba="0.023455 0.023455 0.023455 1" /></material></visual>
    <!--collision>
      <origin rpy="0 0 0" xyz="0 0 0" />
      <geometry>
        <box size="0.3762 0.0935 0.114" />
      </geometry>
    </collision-->
    <collision name="mainbody">
      <origin
        xyz="0 0 -0.07"
        rpy="0 0 0" />
      <geometry>
        <box size="0.33 0.3 0.18"/>
      </geometry>
    </collision>
    <collision name="left">
      <origin
        xyz="0 0.2 -0.035"
        rpy="0 0 0" />
      <geometry>
        <box size="0.1 0.2 0.1"/>
      </geometry>
    </collision>
    <collision name="right">
      <origin
        xyz="0 -0.2 -0.035"
        rpy="0 0 0" />
      <geometry>
        <box size="0.2 0.2 0.1"/>
      </geometry>
    </collision>
    <collision name="back">
      <origin
        xyz="-0.23 0 -0.05"
        rpy="0 0 0" />
      <geometry>
        <box size="0.1 0.1 0.1"/>
      </geometry>
    </collision>
    <collision name="front">
      <origin
        xyz="0.23 0 -0.05"
        rpy="0 0 0" />
      <geometry>
        <box size="0.1 0.1 0.1"/>
      </geometry>
    </collision>
  </link>
  <link name="Head_upper">
    <inertial>
      <origin xyz="0 0 0" rpy="0 0 0" />
      <mass value="0.001" />
      <inertia ixx="9.6e-06" ixy="0" ixz="0" iyy="9.6e-06" iyz="0" izz="9.6e-06" />
    </inertial>
    <collision>
      <origin xyz="0 0 0" rpy="0 0 0" />
      <geometry>
        <cylinder radius="0.05" length="0.09" />
      </geometry>
    </collision>
  </link>
  <joint name="Head_upper_joint" type="fixed" dont_collapse="true">
    <origin xyz="0.285 0 0.01" rpy="0 0 0" />
    <parent link="base" />
    <child link="Head_upper" />
    <axis xyz="0 0 0" />
  </joint>
  <link name="Head_lower">
    <inertial>
      <origin xyz="0 0 0" rpy="0 0 0" />
      <mass value="0.001" />
      <inertia ixx="9.6e-06" ixy="0" ixz="0" iyy="9.6e-06" iyz="0" izz="9.6e-06" />
    </inertial>
    <collision>
      <origin xyz="0 0 0" rpy="0 0 0" />
      <geometry>
        <sphere radius="0.047" />
      </geometry>
    </collision>
  </link>
  <joint name="Head_lower_joint" type="fixed" dont_collapse="true">
    <origin xyz="0.008 0 -0.07" rpy="0 0 0" />
    <parent link="Head_upper" />
    <child link="Head_lower" />
    <axis xyz="0 0 0" />
  </joint>
  <link name="FL_hip">
    <!--inertial>
      <origin xyz="-0.0054 0.00194 -0.000105" rpy="0 0 0" />
      <mass value="0.678" />
      <inertia ixx="0.00048" ixy="-3.01E-06" ixz="1.11E-06" iyy="0.000884" iyz="-1.42E-06" izz="0.000596" />
    </inertial-->
    <inertial>
      <origin xyz="-0.0054 0.00194 -0.000105" rpy="0 0 0" />
      <mass value="1.069" />
      <inertia ixx="0.001411" ixy="2.430E-5" ixz="9.880E-7" iyy="0.002318" iyz="-1.841E-6" izz="0.001739" />
    </inertial>
    <visual>
      <origin xyz="0 0 0" rpy="0 0 0" />
      <geometry>
        <mesh filename="package://go2_description/meshes/hip.dae" />
      </geometry>
      <material name="深色橡胶_001-effect"><color rgba="0.6717055 0.6924257 0.7742702 1" /></material><material name="Material-effect"><color rgba="0.9 0.95 0.95 1" /></material></visual>
    <collision>
      <origin rpy="1.5707963267948966 0 0" xyz="0 0.08 0" />
      <geometry>
        <cylinder length="0.04" radius="0.046" />
      </geometry>
    </collision>
  </link>
  <joint name="FL_hip_joint" type="revolute">
    <origin xyz="0.1934 0.0465 0" rpy="0 0 0" />
    <parent link="base" />
    <child link="FL_hip" />
    <axis xyz="1 0 0" />
    <limit lower="-1.00" upper="0.50" effort="23.7" velocity="30.1" />
  </joint>
  <link name="FL_hip_rotor">
    <inertial>
      <origin rpy="0 0 0" xyz="0.0 0.0 0.0" />
      <mass value="0.089" />
      <inertia ixx="0.000111842" ixy="0.0" ixz="0.0" iyy="0.000059647" iyz="0.0" izz="0.000059647" />
    </inertial>
  </link>
  <joint name="FL_hip_rotor_joint" type="fixed">
    <origin rpy="0 0 0" xyz="0.11215 0.04675 0" />
    <parent link="base" />
    <child link="FL_hip_rotor" />
  </joint>
  <link name="FL_thigh">
    <!--inertial>
      <origin xyz="-0.00374 -0.0223 -0.0327" rpy="0 0 0" />
      <mass value="1.152" />
      <inertia ixx="0.00584" ixy="8.72E-05" ixz="-0.000289" iyy="0.0058" iyz="0.000808" izz="0.00103" />
    </inertial-->
    <inertial>
      <origin xyz="-0.00374 -0.0223 -0.0327" rpy="0 0 0" />
      <mass value="1.257" />
      <inertia ixx="0.003870" ixy="1.630E-5" ixz="-0.000153" iyy="0.004242" iyz="-0.000285" izz="0.001577" />
    </inertial>
    <visual>
      <origin xyz="0 0 0" rpy="0 0 0" />
      <geometry>
        <mesh filename="package://go2_description/meshes/thigh.dae" />
      </geometry>
      <material name="深色橡胶_003-effect"><color rgba="0.6717055 0.6924257 0.7742702 1" /></material><material name="Material_009-effect"><color rgba="0.9 0.95 0.95 1" /></material></visual>
    <collision>
      <origin rpy="0 1.5707963267948966 0" xyz="0 0 -0.1065" />
      <geometry>
        <box size="0.213 0.0245 0.034" />
      </geometry>
    </collision>
  </link>
  <joint name="FL_thigh_joint" type="revolute">
    <origin xyz="0 0.0955 0" rpy="0 0 0" />
    <parent link="FL_hip" />
    <child link="FL_thigh" />
    <axis xyz="0 1 0" />
    <!--limit lower="-1.5708" upper="3.4907" effort="23.7" velocity="30.1" /-->
    <limit lower="-3.2" upper="3.2" effort="23.7" velocity="30.1" />
  </joint>
  <link name="FL_thigh_rotor">
    <inertial>
      <origin rpy="0 0 0" xyz="0.0 0.0 0.0" />
      <mass value="0.089" />
      <inertia ixx="0.000059647" ixy="0.0" ixz="0.0" iyy="0.000111842" iyz="0.0" izz="0.000059647" />
    </inertial>
  </link>
  <joint name="FL_thigh_rotor_joint" type="fixed">
    <origin rpy="0 0 0" xyz="0 -0.00015 0" />
    <parent link="FL_hip" />
    <child link="FL_thigh_rotor" />
  </joint>
  <link name="FL_calf">
    <!--inertial>
      <origin xyz="0.00548 -0.000975 -0.115" rpy="0 0 0" />
      <mass value="0.154" />
      <inertia ixx="0.00108" ixy="3.4E-07" ixz="1.72E-05" iyy="0.0011" iyz="8.28E-06" izz="3.29E-05" />
    </inertial-->
    <inertial>
      <origin xyz="0.00548 -0.000975 -0.115" rpy="0 0 0" />
      <mass value="0.195" />
      <inertia ixx="0.000857" ixy="-3.400E-7" ixz="0.000208" iyy="0.000916" iyz="-2.754E-6" izz="7.237E-5" />
    </inertial>
    <visual>
      <origin xyz="0 0 0" rpy="0 0 0" />
      <geometry>
        <mesh filename="package://go2_description/meshes/calf.dae" />
      </geometry>
      <material name="黑色足端_005-effect"><color rgba="0 0 0 1" /></material><material name="深色橡胶_005-effect"><color rgba="0.6717055 0.6924257 0.7742702 1" /></material></visual>
    <collision>
      <origin rpy="0 -0.21 0" xyz="0.008 0 -0.06" />
      <geometry>
        <cylinder length="0.12" radius="0.012" />
      </geometry>
    </collision>
  </link>
  <joint name="FL_calf_joint" type="revolute">
    <origin xyz="0 0 -0.213" rpy="0 0 0" />
    <parent link="FL_thigh" />
    <child link="FL_calf" />
    <axis xyz="0 1 0" />
    <!--limit lower="-2.7227" upper="2.75" effort="45.43" velocity="15.70" /-->
    <limit lower="-3.2" upper="3.2" effort="45.43" velocity="15.70" />
  </joint>
  <link name="FL_calflower">
    <collision>
      <origin rpy="0 0 0" xyz="0 0 0" />
      <geometry>
        <cylinder length="0.065" radius="0.011" />
      </geometry>
    </collision>
  </link>
  <joint name="FL_calflower_joint" type="fixed">
    <origin xyz="0.020 0 -0.148" rpy="0 0.05 0" />
    <parent link="FL_calf" />
    <child link="FL_calflower" />
    <axis xyz="0 0 0" />
  </joint>
  <link name="FL_calflower1">
    <collision>
      <origin rpy="0 0 0" xyz="0 0 0" />
      <geometry>
        <cylinder length="0.03" radius="0.0155" />
      </geometry>
    </collision>
  </link>
  <joint name="FL_calflower1_joint" type="fixed">
    <origin xyz="-0.01 0 -0.04" rpy="0 0.48 0" />
    <parent link="FL_calflower" />
    <child link="FL_calflower1" />
    <axis xyz="0 0 0" />
  </joint>
  <link name="FL_calf_rotor">
    <inertial>
      <origin rpy="0 0 0" xyz="0.0 0.0 0.0" />
      <mass value="0.089" />
      <inertia ixx="0.000059647" ixy="0.0" ixz="0.0" iyy="0.000111842" iyz="0.0" izz="0.000059647" />
    </inertial>
  </link>
  <joint name="FL_calf_rotor_joint" type="fixed">
    <origin rpy="0 0 0" xyz="0 -0.03235 0" />
    <parent link="FL_thigh" />
    <child link="FL_calf_rotor" />
  </joint>
  <link name="FL_foot">
    <inertial>
      <origin xyz="0 0 0" rpy="0 0 0" />
      <mass value="0.04" />
      <inertia ixx="9.6e-06" ixy="0" ixz="0" iyy="9.6e-06" iyz="0" izz="9.6e-06" />
    </inertial>
    <visual>
      <origin xyz="0 0 0" rpy="0 0 0" />
      <geometry>
        <mesh filename="package://go2_description/meshes/foot.dae" />
      </geometry>
      <material name="黑色足端_007-effect"><color rgba="0 0 0 1" /></material></visual>
    <collision>
      <origin rpy="0 0 0" xyz="-0.002 0 0" />
      <geometry>
        <sphere radius="0.022" />
      </geometry>
    </collision>
  </link>
  <joint name="FL_foot_joint" type="fixed" dont_collapse="true">
    <origin xyz="0 0 -0.213" rpy="0 0 0" />
    <parent link="FL_calf" />
    <child link="FL_foot" />
    <axis xyz="0 0 0" />
  </joint>
  <link name="FR_hip">
    <!--inertial>
      <origin xyz="-0.0054 -0.00194 -0.000105" rpy="0 0 0" />
      <mass value="0.678" />
      <inertia ixx="0.00048" ixy="3.01E-06" ixz="1.11E-06" iyy="0.000884" iyz="1.42E-06" izz="0.000596" />
    </inertial-->
    <inertial>
      <origin xyz="-0.0054 -0.00194 -0.000105" rpy="0 0 0" />
      <mass value="1.069" />
      <inertia ixx="0.001411" ixy="-2.441E-5" ixz="9.740E-7" iyy="0.002318" iyz="1.841E-6" izz="0.001739" />
    </inertial>
    <visual>
      <origin xyz="0 0 0" rpy="3.1415 0 0" />
      <geometry>
        <mesh filename="package://go2_description/meshes/hip.dae" />
      </geometry>
      <material name="深色橡胶_001-effect"><color rgba="0.6717055 0.6924257 0.7742702 1" /></material><material name="Material-effect"><color rgba="0.9 0.95 0.95 1" /></material></visual>
    <collision>
      <origin rpy="1.5707963267948966 0 0" xyz="0 -0.08 0" />
      <geometry>
        <cylinder length="0.04" radius="0.046" />
      </geometry>
    </collision>
  </link>
  <joint name="FR_hip_joint" type="revolute">
    <origin xyz="0.1934 -0.0465 0" rpy="0 0 0" />
    <parent link="base" />
    <child link="FR_hip" />
    <axis xyz="1 0 0" />
    <limit lower="-0.50" upper="1.00" effort="23.7" velocity="30.1" />
  </joint>
  <link name="FR_hip_rotor">
    <inertial>
      <origin rpy="0 0 0" xyz="0.0 0.0 0.0" />
      <mass value="0.089" />
      <inertia ixx="0.000111842" ixy="0.0" ixz="0.0" iyy="0.000059647" iyz="0.0" izz="0.000059647" />
    </inertial>
  </link>
  <joint name="FR_hip_rotor_joint" type="fixed">
    <origin rpy="0 0 0" xyz="0.11215 -0.04675 0" />
    <parent link="base" />
    <child link="FR_hip_rotor" />
  </joint>
  <link name="FR_thigh">
    <!--inertial>
      <origin xyz="-0.00374 0.0223 -0.0327" rpy="0 0 0" />
      <mass value="1.152" />
      <inertia ixx="0.00584" ixy="-8.72E-05" ixz="-0.000289" iyy="0.0058" iyz="-0.000808" izz="0.00103" />
    </inertial-->
    <inertial>
      <origin xyz="-0.00374 0.0223 -0.0327" rpy="0 0 0" />
      <mass value="1.257" />
      <inertia ixx="0.003781" ixy="-1.796E-5" ixz="-0.000155" iyy="0.004239" iyz="0.000283" izz="0.001664" />
    </inertial>
    <visual>
      <origin xyz="0 0 0" rpy="0 0 0" />
      <geometry>
        <mesh filename="package://go2_description/meshes/thigh_mirror.dae" />
      </geometry>
      <material name="深色橡胶_012-effect"><color rgba="0.6717055 0.6924257 0.7742702 1" /></material><material name="Material_011-effect"><color rgba="0.9 0.95 0.95 1" /></material></visual>
    <collision>
      <origin rpy="0 1.5707963267948966 0" xyz="0 0 -0.1065" />
      <geometry>
        <box size="0.213 0.0245 0.034" />
      </geometry>
    </collision>
  </link>
  <joint name="FR_thigh_joint" type="revolute">
    <origin xyz="0 -0.0955 0" rpy="0 0 0" />
    <parent link="FR_hip" />
    <child link="FR_thigh" />
    <axis xyz="0 1 0" />
    <!--limit lower="-1.5708" upper="3.4907" effort="23.7" velocity="30.1" /-->
    <limit lower="-3.2" upper="3.2" effort="23.7" velocity="30.1" />
  </joint>
  <link name="FR_thigh_rotor">
    <inertial>
      <origin rpy="0 0 0" xyz="0.0 0.0 0.0" />
      <mass value="0.089" />
      <inertia ixx="0.000059647" ixy="0.0" ixz="0.0" iyy="0.000111842" iyz="0.0" izz="0.000059647" />
    </inertial>
  </link>
  <joint name="FR_thigh_rotor_joint" type="fixed">
    <origin rpy="0 0 0" xyz="0 0.00015 0" />
    <parent link="FR_hip" />
    <child link="FR_thigh_rotor" />
  </joint>
  <link name="FR_calf">
    <!--inertial>
      <origin xyz="0.00548 0.000975 -0.115" rpy="0 0 0" />
      <mass value="0.154" />
      <inertia ixx="0.00108" ixy="-3.4E-07" ixz="1.72E-05" iyy="0.0011" iyz="-8.28E-06" izz="3.29E-05" />
    </inertial-->
    <inertial>
      <origin xyz="0.00548 0.000975 -0.115" rpy="0 0 0" />
      <mass value="0.195" />
      <inertia ixx="0.000857" ixy="3.400E-7" ixz="0.000208" iyy="0.000916" iyz="2.754E-6" izz="7.237E-5" />
    </inertial>
    <visual>
      <origin xyz="0 0 0" rpy="0 0 0" />
      <geometry>
        <mesh filename="package://go2_description/meshes/calf_mirror.dae" />
      </geometry>
      <material name="黑色足端_006-effect"><color rgba="0 0 0 1" /></material><material name="深色橡胶_007-effect"><color rgba="0.6717055 0.6924257 0.7742702 1" /></material></visual>
    <collision>
      <origin rpy="0 -0.2 0" xyz="0.01 0 -0.06" />
      <geometry>
        <cylinder length="0.12" radius="0.013" />
      </geometry>
    </collision>
  </link>
  <joint name="FR_calf_joint" type="revolute">
    <origin xyz="0 0 -0.213" rpy="0 0 0" />
    <parent link="FR_thigh" />
    <child link="FR_calf" />
    <axis xyz="0 1 0" />
    <!--limit lower="-2.7227" upper="2.75" effort="45.43" velocity="15.70" /-->
    <limit lower="-3.2" upper="3.2" effort="45.43" velocity="15.70" />
  </joint>
  <link name="FR_calflower">
    <collision>
      <origin rpy="0 0 0" xyz="0 0 0" />
      <geometry>
        <cylinder length="0.065" radius="0.011" />
      </geometry>
    </collision>
  </link>
  <joint name="FR_calflower_joint" type="fixed">
    <origin xyz="0.020 0 -0.148" rpy="0 0.05 0" />
    <parent link="FR_calf" />
    <child link="FR_calflower" />
    <axis xyz="0 0 0" />
  </joint>
  <link name="FR_calflower1">
    <collision>
      <origin rpy="0 0 0" xyz="0 0 0" />
      <geometry>
        <cylinder length="0.03" radius="0.0155" />
      </geometry>
    </collision>
  </link>
  <joint name="FR_calflower1_joint" type="fixed">
    <origin xyz="-0.01 0 -0.04" rpy="0 0.48 0" />
    <parent link="FR_calflower" />
    <child link="FR_calflower1" />
    <axis xyz="0 0 0" />
  </joint>
  <link name="FR_calf_rotor">
    <inertial>
      <origin rpy="0 0 0" xyz="0.0 0.0 0.0" />
      <mass value="0.089" />
      <inertia ixx="0.000059647" ixy="0.0" ixz="0.0" iyy="0.000111842" iyz="0.0" izz="0.000059647" />
    </inertial>
  </link>
  <joint name="FR_calf_rotor_joint" type="fixed">
    <origin rpy="0 0 0" xyz="0 0.03235 0" />
    <parent link="FR_thigh" />
    <child link="FR_calf_rotor" />
  </joint>
  <link name="FR_foot">
    <inertial>
      <origin xyz="0 0 0" rpy="0 0 0" />
      <mass value="0.04" />
      <inertia ixx="9.6e-06" ixy="0" ixz="0" iyy="9.6e-06" iyz="0" izz="9.6e-06" />
    </inertial>
    <visual>
      <origin xyz="0 0 0" rpy="0 0 0" />
      <geometry>
        <mesh filename="package://go2_description/meshes/foot.dae" />
      </geometry>
      <material name="黑色足端_007-effect"><color rgba="0 0 0 1" /></material></visual>
    <collision>
      <origin rpy="0 0 0" xyz="-0.002 0 0" />
      <geometry>
        <sphere radius="0.022" />
      </geometry>
    </collision>
  </link>
  <joint name="FR_foot_joint" type="fixed" dont_collapse="true">
    <origin xyz="0 0 -0.213" rpy="0 0 0" />
    <parent link="FR_calf" />
    <child link="FR_foot" />
    <axis xyz="0 0 0" />
  </joint>
  <link name="RL_hip">
    <!--inertial>
      <origin xyz="0.0054 0.00194 -0.000105" rpy="0 0 0" />
      <mass value="0.678" />
      <inertia ixx="0.00048" ixy="3.01E-06" ixz="-1.11E-06" iyy="0.000884" iyz="-1.42E-06" izz="0.000596" />
    </inertial-->
    <inertial>
      <origin xyz="0.0054 0.00194 -0.000105" rpy="0 0 0" />
      <mass value="1.069477" />
      <inertia ixx="0.001411" ixy="-2.441E-5" ixz="-9.740E-7" iyy="0.002318" iyz="-1.841E-6" izz="0.001739" />
    </inertial>
    <visual>
      <origin xyz="0 0 0" rpy="0 3.1415 0" />
      <geometry>
        <mesh filename="package://go2_description/meshes/hip.dae" />
      </geometry>
      <material name="深色橡胶_001-effect"><color rgba="0.6717055 0.6924257 0.7742702 1" /></material><material name="Material-effect"><color rgba="0.9 0.95 0.95 1" /></material></visual>
    <collision>
      <origin rpy="1.5707963267948966 0 0" xyz="0 0.08 0" />
      <geometry>
        <cylinder length="0.04" radius="0.046" />
      </geometry>
    </collision>
  </link>
  <joint name="RL_hip_joint" type="revolute">
    <origin xyz="-0.1934 0.0465 0" rpy="0 0 0" />
    <parent link="base" />
    <child link="RL_hip" />
    <axis xyz="1 0 0" />
    <limit lower="-1.00" upper="0.50" effort="23.7" velocity="30.1" />
  </joint>
  <link name="RL_hip_rotor">
    <inertial>
      <origin rpy="0 0 0" xyz="0.0 0.0 0.0" />
      <mass value="0.089" />
      <inertia ixx="0.000111842" ixy="0.0" ixz="0.0" iyy="0.000059647" iyz="0.0" izz="0.000059647" />
    </inertial>
  </link>
  <joint name="RL_hip_rotor_joint" type="fixed">
    <origin rpy="0 0 0" xyz="-0.11215 0.04675 0" />
    <parent link="base" />
    <child link="RL_hip_rotor" />
  </joint>
  <link name="RL_thigh">
    <!--inertial>
      <origin xyz="-0.00374 -0.0223 -0.0327" rpy="0 0 0" />
      <mass value="1.152" />
      <inertia ixx="0.00584" ixy="8.72E-05" ixz="-0.000289" iyy="0.0058" iyz="0.000808" izz="0.00103" />
    </inertial-->
    <inertial>
      <origin xyz="-0.00374 -0.0223 -0.0327" rpy="0 0 0" />
      <mass value="1.256985" />
      <inertia ixx="0.003781" ixy="-1.796E-5" ixz="0.000155" iyy="0.004239" iyz="-0.000283" izz="0.001664" />
    </inertial>
    <visual>
      <origin xyz="0 0 0" rpy="0 0 0" />
      <geometry>
        <mesh filename="package://go2_description/meshes/thigh.dae" />
      </geometry>
      <material name="深色橡胶_003-effect"><color rgba="0.6717055 0.6924257 0.7742702 1" /></material><material name="Material_009-effect"><color rgba="0.9 0.95 0.95 1" /></material></visual>
    <collision>
      <origin rpy="0 1.5707963267948966 0" xyz="0 0 -0.1065" />
      <geometry>
        <box size="0.213 0.0245 0.034" />
      </geometry>
    </collision>
  </link>
  <joint name="RL_thigh_joint" type="revolute">
    <origin xyz="0 0.0955 0" rpy="0 0 0" />
    <parent link="RL_hip" />
    <child link="RL_thigh" />
    <axis xyz="0 1 0" />
    <!--limit lower="-3.4907" upper="1.5708" effort="23.7" velocity="30.1" /-->
    <limit lower="-3.2" upper="3.2" effort="23.7" velocity="30.1" />
  </joint>
  <link name="RL_thigh_rotor">
    <inertial>
      <origin rpy="0 0 0" xyz="0.0 0.0 0.0" />
      <mass value="0.089" />
      <inertia ixx="0.000059647" ixy="0.0" ixz="0.0" iyy="0.000111842" iyz="0.0" izz="0.000059647" />
    </inertial>
  </link>
  <joint name="RL_thigh_rotor_joint" type="fixed">
    <origin rpy="0 0 0" xyz="0 -0.00015 0" />
    <parent link="RL_hip" />
    <child link="RL_thigh_rotor" />
  </joint>
  <link name="RL_calf">
    <!--inertial>
      <origin xyz="0.00548 -0.000975 -0.115" rpy="0 0 0" />
      <mass value="0.154" />
      <inertia ixx="0.00108" ixy="3.4E-07" ixz="1.72E-05" iyy="0.0011" iyz="8.28E-06" izz="3.29E-05" />
    </inertial-->
    <inertial>
      <origin xyz="0.00548 -0.000975 -0.115" rpy="0 0 0" />
      <mass value="0.194642" />
      <inertia ixx="0.000857" ixy="3.402E-7" ixz="-0.000208" iyy="0.000916" iyz="-2.754E-6" izz="7.237E-5" />
    </inertial>
    <visual>
      <origin xyz="0 0 0" rpy="0 0 0" />
      <geometry>
        <mesh filename="package://go2_description/meshes/calf.dae" />
      </geometry>
      <material name="黑色足端_005-effect"><color rgba="0 0 0 1" /></material><material name="深色橡胶_005-effect"><color rgba="0.6717055 0.6924257 0.7742702 1" /></material></visual>
    <collision>
      <origin rpy="0 -0.2 0" xyz="0.01 0 -0.06" />
      <geometry>
        <cylinder length="0.12" radius="0.013" />
      </geometry>
    </collision>
  </link>
  <joint name="RL_calf_joint" type="revolute">
    <origin xyz="0 0 -0.213" rpy="0 0 0" />
    <parent link="RL_thigh" />
    <child link="RL_calf" />
    <axis xyz="0 1 0" />
    <!--limit lower="-2.7227" upper="2.75" effort="45.43" velocity="15.70" /-->
    <limit lower="-3.2" upper="3.2" effort="45.43" velocity="15.70" />
  </joint>
  <link name="RL_calflower">
    <collision>
      <origin rpy="0 0 0" xyz="0 0 0" />
      <geometry>
        <cylinder length="0.065" radius="0.011" />
      </geometry>
    </collision>
  </link>
  <joint name="RL_calflower_joint" type="fixed">
    <origin xyz="0.020 0 -0.148" rpy="0 0.05 0" />
    <parent link="RL_calf" />
    <child link="RL_calflower" />
    <axis xyz="0 0 0" />
  </joint>
  <link name="RL_calflower1">
    <collision>
      <origin rpy="0 0 0" xyz="0 0 0" />
      <geometry>
        <cylinder length="0.03" radius="0.0155" />
      </geometry>
    </collision>
  </link>
  <joint name="RL_calflower1_joint" type="fixed">
    <origin xyz="-0.01 0 -0.04" rpy="0 0.48 0" />
    <parent link="RL_calflower" />
    <child link="RL_calflower1" />
    <axis xyz="0 0 0" />
  </joint>
  <link name="RL_calf_rotor">
    <inertial>
      <origin rpy="0 0 0" xyz="0.0 0.0 0.0" />
      <mass value="0.089" />
      <inertia ixx="0.000059647" ixy="0.0" ixz="0.0" iyy="0.000111842" iyz="0.0" izz="0.000059647" />
    </inertial>
  </link>
  <joint name="RL_calf_rotor_joint" type="fixed">
    <origin rpy="0 0 0" xyz="0 -0.03235 0" />
    <parent link="RL_thigh" />
    <child link="RL_calf_rotor" />
  </joint>
  <link name="RL_foot">
    <inertial>
      <origin xyz="0 0 0" rpy="0 0 0" />
      <mass value="0.04" />
      <inertia ixx="9.6e-06" ixy="0" ixz="0" iyy="9.6e-06" iyz="0" izz="9.6e-06" />
    </inertial>
    <visual>
      <origin xyz="0 0 0" rpy="0 0 0" />
      <geometry>
        <mesh filename="package://go2_description/meshes/foot.dae" />
      </geometry>
      <material name="黑色足端_007-effect"><color rgba="0 0 0 1" /></material></visual>
    <collision>
      <origin rpy="0 0 0" xyz="-0.002 0 0" />
      <geometry>
        <sphere radius="0.022" />
      </geometry>
    </collision>
  </link>
  <joint name="RL_foot_joint" type="fixed" dont_collapse="true">
    <origin xyz="0 0 -0.213" rpy="0 0 0" />
    <parent link="RL_calf" />
    <child link="RL_foot" />
    <axis xyz="0 0 0" />
  </joint>
  <link name="RR_hip">
    <!--inertial>
      <origin xyz="0.0054 -0.00194 -0.000105" rpy="0 0 0" />
      <mass value="0.678" />
      <inertia ixx="0.00048" ixy="-3.01E-06" ixz="-1.11E-06" iyy="0.000884" iyz="1.42E-06" izz="0.000596" />
    </inertial-->
    <inertial>
      <origin xyz="0.0054 -0.00194 -0.000105" rpy="0 0 0" />
      <mass value="1.069477" />
      <inertia ixx="0.001411" ixy="2.430E-5" ixz="-9.876E-7" iyy="0.002318" iyz="1.841E-6" izz="0.001739" />
    </inertial>
    <visual>
      <origin xyz="0 0 0" rpy="3.1415 3.1415 0" />
      <geometry>
        <mesh filename="package://go2_description/meshes/hip.dae" />
      </geometry>
      <material name="深色橡胶_001-effect"><color rgba="0.6717055 0.6924257 0.7742702 1" /></material><material name="Material-effect"><color rgba="0.9 0.95 0.95 1" /></material></visual>
    <collision>
      <origin rpy="1.5707963267948966 0 0" xyz="0 -0.08 0" />
      <geometry>
        <cylinder length="0.04" radius="0.046" />
      </geometry>
    </collision>
  </link>
  <joint name="RR_hip_joint" type="revolute">
    <origin xyz="-0.1934 -0.0465 0" rpy="0 0 0" />
    <parent link="base" />
    <child link="RR_hip" />
    <axis xyz="1 0 0" />
    <limit lower="-0.50" upper="1.00" effort="23.7" velocity="30.1" />
  </joint>
  <link name="RR_hip_rotor">
    <inertial>
      <origin rpy="0 0 0" xyz="0.0 0.0 0.0" />
      <mass value="0.089" />
      <inertia ixx="0.000111842" ixy="0.0" ixz="0.0" iyy="0.000059647" iyz="0.0" izz="0.000059647" />
    </inertial>
  </link>
  <joint name="RR_hip_rotor_joint" type="fixed">
    <origin rpy="0 0 0" xyz="-0.11215 -0.04675 0" />
    <parent link="base" />
    <child link="RR_hip_rotor" />
  </joint>
  <link name="RR_thigh">
    <!--inertial>
      <origin xyz="-0.00374 0.0223 -0.0327" rpy="0 0 0" />
      <mass value="1.152" />
      <inertia ixx="0.00584" ixy="-8.72E-05" ixz="-0.000289" iyy="0.0058" iyz="-0.000808" izz="0.00103" />
    </inertial-->
    <inertial>
      <origin xyz="-0.00374 0.0223 -0.0327" rpy="0 0 0" />
      <mass value="1.256985" />
      <inertia ixx="0.003870" ixy="1.630E-5" ixz="0.000153" iyy="0.004242" iyz="0.000285" izz="0.001577" />
    </inertial>
    <visual>
      <origin xyz="0 0 0" rpy="0 0 0" />
      <geometry>
        <mesh filename="package://go2_description/meshes/thigh_mirror.dae" />
      </geometry>
      <material name="深色橡胶_012-effect"><color rgba="0.6717055 0.6924257 0.7742702 1" /></material><material name="Material_011-effect"><color rgba="0.9 0.95 0.95 1" /></material></visual>
    <collision>
      <origin rpy="0 1.5707963267948966 0" xyz="0 0 -0.1065" />
      <geometry>
        <box size="0.213 0.0245 0.034" />
      </geometry>
    </collision>
  </link>
  <joint name="RR_thigh_joint" type="revolute">
    <origin xyz="0 -0.0955 0" rpy="0 0 0" />
    <parent link="RR_hip" />
    <child link="RR_thigh" />
    <axis xyz="0 1 0" />
    <!--limit lower="-3.4907" upper="1.5708" effort="23.7" velocity="30.1" /-->
    <limit lower="-3.2" upper="3.2" effort="23.7" velocity="30.1" />
  </joint>
  <link name="RR_thigh_rotor">
    <inertial>
      <origin rpy="0 0 0" xyz="0.0 0.0 0.0" />
      <mass value="0.089" />
      <inertia ixx="0.000059647" ixy="0.0" ixz="0.0" iyy="0.000111842" iyz="0.0" izz="0.000059647" />
    </inertial>
  </link>
  <joint name="RR_thigh_rotor_joint" type="fixed">
    <origin rpy="0 0 0" xyz="0 0.00015 0" />
    <parent link="RR_hip" />
    <child link="RR_thigh_rotor" />
  </joint>
  <link name="RR_calf">
    <!--inertial>
      <origin xyz="0.00548 0.000975 -0.115" rpy="0 0 0" />
      <mass value="0.154" />
      <inertia ixx="0.00108" ixy="-3.4E-07" ixz="1.72E-05" iyy="0.0011" iyz="-8.28E-06" izz="3.29E-05" />
    </inertial-->
    <inertial>
      <origin xyz="0.00548 0.000975 -0.115" rpy="0 0 0" />
      <mass value="0.194642" />
      <inertia ixx="0.000857" ixy="-3.402E-7" ixz="-0.000208" iyy="0.000916" iyz="2.754E-6" izz="7.237E-5" />
    </inertial>
    <visual>
      <origin xyz="0 0 0" rpy="0 0 0" />
      <geometry>
        <mesh filename="package://go2_description/meshes/calf_mirror.dae" />
      </geometry>
      <material name="黑色足端_006-effect"><color rgba="0 0 0 1" /></material><material name="深色橡胶_007-effect"><color rgba="0.6717055 0.6924257 0.7742702 1" /></material></visual>
    <collision>
      <origin rpy="0 -0.2 0" xyz="0.01 0 -0.06" />
      <geometry>
        <cylinder length="0.12" radius="0.013" />
      </geometry>
    </collision>
  </link>
  <joint name="RR_calf_joint" type="revolute">
    <origin xyz="0 0 -0.213" rpy="0 0 0" />
    <parent link="RR_thigh" />
    <child link="RR_calf" />
    <axis xyz="0 1 0" />
    <!--limit lower="-2.7227" upper="2.75" effort="45.43" velocity="15.70" /-->
    <limit lower="-3.2" upper="3.2" effort="45.43" velocity="15.70" />
  </joint>
  <link name="RR_calflower">
    <collision>
      <origin rpy="0 0 0" xyz="0 0 0" />
      <geometry>
        <cylinder length="0.065" radius="0.011" />
      </geometry>
    </collision>
  </link>
  <joint name="RR_calflower_joint" type="fixed">
    <origin xyz="0.020 0 -0.148" rpy="0 0.05 0" />
    <parent link="RR_calf" />
    <child link="RR_calflower" />
    <axis xyz="0 0 0" />
  </joint>
  <link name="RR_calflower1">
    <collision>
      <origin rpy="0 0 0" xyz="0 0 0" />
      <geometry>
        <cylinder length="0.03" radius="0.0155" />
      </geometry>
    </collision>
  </link>
  <joint name="RR_calflower1_joint" type="fixed">
    <origin xyz="-0.01 0 -0.04" rpy="0 0.48 0" />
    <parent link="RR_calflower" />
    <child link="RR_calflower1" />
    <axis xyz="0 0 0" />
  </joint>
  <link name="RR_calf_rotor">
    <inertial>
      <origin rpy="0 0 0" xyz="0.0 0.0 0.0" />
      <mass value="0.089" />
      <inertia ixx="0.000059647" ixy="0.0" ixz="0.0" iyy="0.000111842" iyz="0.0" izz="0.000059647" />
    </inertial>
  </link>
  <joint name="RR_calf_rotor_joint" type="fixed">
    <origin rpy="0 0 0" xyz="0 0.03235 0" />
    <parent link="RR_thigh" />
    <child link="RR_calf_rotor" />
  </joint>
  <link name="RR_foot">
    <inertial>
      <origin xyz="0 0 0" rpy="0 0 0" />
      <mass value="0.04" />
      <inertia ixx="9.6e-06" ixy="0" ixz="0" iyy="9.6e-06" iyz="0" izz="9.6e-06" />
    </inertial>
    <visual>
      <origin xyz="0 0 0" rpy="0 0 0" />
      <geometry>
        <mesh filename="package://go2_description/meshes/foot.dae" />
      </geometry>
      <material name="黑色足端_007-effect"><color rgba="0 0 0 1" /></material></visual>
    <collision>
      <origin rpy="0 0 0" xyz="-0.002 0 0" />
      <geometry>
        <sphere radius="0.022" />
      </geometry>
    </collision>
  </link>
  <joint name="RR_foot_joint" type="fixed" dont_collapse="true">
    <origin xyz="0 0 -0.213" rpy="0 0 0" />
    <parent link="RR_calf" />
    <child link="RR_foot" />
    <axis xyz="0 0 0" />
  </joint>
  <link name="imu">
    <inertial>
      <origin xyz="0 0 0" rpy="0 0 0" />
      <mass value="0" />
      <inertia ixx="0" ixy="0" ixz="0" iyy="0" iyz="0" izz="0" />
    </inertial>
  </link>
  <joint name="imu_joint" type="fixed">
    <origin xyz="-0.02557 0 0.04232" rpy="0 0 0" />
    <parent link="base" />
    <child link="imu" />
    <axis xyz="0 0 0" />
  </joint>
  <link name="radar">
    <inertial>
      <origin xyz="0 0 0" rpy="0 0 0" />
      <mass value="0" />
      <inertia ixx="0" ixy="0" ixz="0" iyy="0" iyz="0" izz="0" />
    </inertial>
  </link>
  <joint name="radar_joint" type="fixed">
    <origin xyz="0.28945 0 -0.046825" rpy="0 2.8782 0" />
    <parent link="base" />
    <child link="radar" />
    <axis xyz="0 0 0" />
  </joint>
  <joint name="front_camera_joint" type="fixed">
    <origin rpy="0 0 0" xyz="0.32715 -0.00003 0.04297" />
      <parent link="base" />
      <child link="front_camera" />
  </joint>
  <link name="front_camera">
  </link>
  <link
    name="left_arm1">
    <inertial>
      <origin
        xyz="0.000004 0.004168 0.033215"
        rpy="0 0 0" />
      <mass
        value="0.515038" />
      <inertia
        ixx="0.000328"
        ixy="-1.547E-8"
        ixz="3.297E-7"
        iyy="0.000243"
        iyz="-1.438E-5"
        izz="0.000297" />
    </inertial>
    <visual>
      <origin
        xyz="0 0 0"
        rpy="0 0 0" />
      <geometry>
        <mesh
          filename="../meshes/left_arm1.STL" />
      </geometry>
      <material
        name="">
        <color
          rgba="0.89804 0.91765 0.92941 1" />
      </material>
    </visual>
    <!--collision>
      <origin
        xyz="0 0 0"
        rpy="0 0 0" />
      <geometry>
        <mesh
          filename="../meshes/left_arm1.STL" />
      </geometry>
    </collision-->
  </link>
  <!--joint
    name="left_arm_j1"
    type="revolute">
    <origin
      xyz="0.29825 -0.085 0.025"
      rpy="0 0 -1.5708" />
    <parent
      link="base" />
    <child
      link="left_arm1" />
    <axis
      xyz="0 0 -1" />
    <limit
      lower="-3"
      upper="3"
      effort="75"
      velocity="58.5" />
  </joint-->
  <joint
    name="left_arm_j1"
    type="fixed"
    dont_collapse="true">
    <origin
      xyz="0.1 -0.085 0.05"
      rpy="0 0 -1.5708" />
    <parent
      link="base" />
    <child
      link="left_arm1" />
    <axis
      xyz="0 0 0" />
  </joint>
  <link
    name="left_arm2">
    <inertial>
      <origin
        xyz="-0.119400 0.000098 0.013073"
        rpy="0 0 0" />
      <mass
        value="0.266875" />
      <inertia
        ixx="0.000074"
        ixy="1.000E-10"
        ixz="1.000E-10"
        iyy="0.002702"
        iyz="1.031E-7"
        izz="0.002741" />
    </inertial>
    <visual>
      <origin
        xyz="0 0 0"
        rpy="0 0 0" />
      <geometry>
        <mesh
          filename="../meshes/left_arm2.STL" />
      </geometry>
      <material
        name="">
        <color
          rgba="0.89804 0.91765 0.92941 1" />
      </material>
    </visual>
    <!--collision>
      <origin
        xyz="0 0 0"
        rpy="0 0 0" />
      <geometry>
        <mesh
          filename="../meshes/left_arm2.STL" />
      </geometry>
    </collision-->
  </link>
  <!--joint
    name="left_arm_j2"
    type="revolute">
    <origin
      xyz="0 0.038 0.036"
      rpy="-1.5708 0 0" />
    <parent
      link="left_arm1" />
    <child
      link="left_arm2" />
    <axis
      xyz="0 0 1" />
    <limit
      lower="0"
      upper="3"
      effort="75"
      velocity="58.5" />
  </joint-->
  <joint
    name="left_arm_j2"
    type="fixed"
    dont_collapse="true">
    <origin
      xyz="0 0.038 0.036"
      rpy="-1.5708 0 0" />
    <parent
      link="left_arm1" />
    <child
      link="left_arm2" />
    <axis
      xyz="0 0 0" />
  </joint>
  <link
    name="left_arm3">
    <inertial>
      <origin
        xyz="0.148986 0.047869 -0.006891"
        rpy="0 0 0" />
      <mass
        value="2.186092" />
      <inertia
        ixx="0.007971"
        ixy="0.006065"
        ixz="-0.005778"
        iyy="0.025569"
        iyz="-0.001861"
        izz="0.022958" />
    </inertial>
    <visual>
      <origin
        xyz="0 0 0"
        rpy="0 0 0" />
      <geometry>
        <mesh
          filename="../meshes/left_arm3.STL" />
      </geometry>
      <material
        name="">
        <color
          rgba="0.89804 0.91765 0.92941 1" />
      </material>
    </visual>
    <!--collision>
      <origin
        xyz="0 0 0"
        rpy="0 0 0" />
      <geometry>
        <mesh
          filename="../meshes/left_arm3.STL" />
      </geometry>
    </collision-->
  </link>
  <!--joint
    name="left_arm_j3"
    type="revolute">
    <origin
      xyz="-0.2388 0 -0.009"
      rpy="3.1416 0 0" />
    <parent
      link="left_arm2" />
    <child
      link="left_arm3" />
    <axis
      xyz="0 0 -1" />
    <limit
      lower="-3"
      upper="3"
      effort="75"
      velocity="58.5" />
  </joint-->
  <joint
    name="left_arm_j3"
    type="fixed"
    dont_collapse="true">
    <origin
      xyz="-0.2388 0 -0.009"
      rpy="3.1416 0 0" />
    <parent
      link="left_arm2" />
    <child
      link="left_arm3" />
    <axis
      xyz="0 0 0" />
  </joint>
  <link
    name="right_arm1">
    <inertial>
      <origin
        xyz="-0.000004 -0.004168 0.033215"
        rpy="0 0 0" />
      <mass
        value="0.515038" />
      <inertia
        ixx="0.000328"
        ixy="-1.547E-8"
        ixz="-3.297E-7"
        iyy="0.000243"
        iyz="1.438E-5"
        izz="0.000297" />
    </inertial>
    <visual>
      <origin
        xyz="0 0 0"
        rpy="0 0 0" />
      <geometry>
        <mesh
          filename="../meshes/right_arm1.STL" />
      </geometry>
      <material
        name="">
        <color
          rgba="0.75294 0.75294 0.75294 1" />
      </material>
    </visual>
    <!--collision>
      <origin
        xyz="0 0 0"
        rpy="0 0 0" />
      <geometry>
        <mesh
          filename="../meshes/right_arm1.STL" />
      </geometry>
    </collision-->
  </link>
  <!--joint
    name="right_arm_j1"
    type="revolute">
    <origin
      xyz="0.078254 -0.085 0.025"
      rpy="0 0 -1.5708" />
    <parent
      link="base" />
    <child
      link="right_arm1" />
    <axis
      xyz="0 0 -1" />
    <limit
      lower="-3"
      upper="3"
      effort="75"
      velocity="58.5" />
  </joint-->
  <joint
    name="right_arm_j1"
    type="fixed"
    dont_collapse="true">
    <origin
      xyz="-0.1 -0.085 0.05"
      rpy="0 0 -1.5708" />
    <parent
      link="base" />
    <child
      link="right_arm1" />
    <axis
      xyz="0 0 0" />
  </joint>
  <link
    name="right_arm2">
    <inertial>
      <origin
        xyz="-0.119400 -0.000098 0.013073"
        rpy="0 0 0" />
      <mass
        value="0.266875" />
      <inertia
        ixx="0.000074"
        ixy="1.000E-10"
        ixz="1.000E-10"
        iyy="0.002702"
        iyz="-1.031E-7"
        izz="0.002741" />
    </inertial>
    <visual>
      <origin
        xyz="0 0 0"
        rpy="0 0 0" />
      <geometry>
        <mesh
          filename="../meshes/right_arm2.STL" />
      </geometry>
      <material
        name="">
        <color
          rgba="0.89804 0.91765 0.92941 1" />
      </material>
    </visual>
    <!--collision>
      <origin
        xyz="0 0 0"
        rpy="0 0 0" />
      <geometry>
        <mesh
          filename="../meshes/right_arm2.STL" />
      </geometry>
    </collision-->
  </link>
  <!--joint
    name="right_arm_j2"
    type="revolute">
    <origin
      xyz="0 -0.038 0.036"
      rpy="1.5708 0 0" />
    <parent
      link="right_arm1" />
    <child
      link="right_arm2" />
    <axis
      xyz="0 0 -1" />
    <limit
      lower="0"
      upper="3"
      effort="75"
      velocity="58.5" />
  </joint-->
  <joint
    name="right_arm_j2"
    type="fixed"
    dont_collapse="true">
    <origin
      xyz="0 -0.038 0.036"
      rpy="1.5708 0 0" />
    <parent
      link="right_arm1" />
    <child
      link="right_arm2" />
    <axis
      xyz="0 0 0" />
  </joint>
  <link
    name="right_arm3">
    <inertial>
      <origin
        xyz="0.149378 -0.047869 -0.006894"
        rpy="0 0 0" />
      <mass
        value="2.186092" />
      <inertia
        ixx="0.007982"
        ixy="-0.005921"
        ixz="-0.005863"
        iyy="0.025686"
        iyz="0.001857"
        izz="0.023088" />
    </inertial>
    <visual>
      <origin
        xyz="0 0 0"
        rpy="0 0 0" />
      <geometry>
        <mesh
          filename="../meshes/right_arm3.STL" />
      </geometry>
      <material
        name="">
        <color
          rgba="0.89804 0.91765 0.92941 1" />
      </material>
    </visual>
    <!--collision>
      <origin
        xyz="0 0 0"
        rpy="0 0 0" />
      <geometry>
        <mesh
          filename="../meshes/right_arm3.STL" />
      </geometry>
    </collision-->
  </link>
  <!--joint
    name="right_arm_j3"
    type="revolute">
    <origin
      xyz="-0.2388 0 -0.009"
      rpy="-3.1416 0 0" />
    <parent
      link="right_arm2" />
    <child
      link="right_arm3" />
    <axis
      xyz="0 0 1" />
    <limit
      lower="-3"
      upper="3"
      effort="75"
      velocity="58.5" />
  </joint-->
  <joint
    name="right_arm_j3"
    type="fixed"
    dont_collapse="true">
    <origin
      xyz="-0.2388 0 -0.009"
      rpy="-3.1416 0 0" />
    <parent
      link="right_arm2" />
    <child
      link="right_arm3" />
    <axis
      xyz="0 0 0" />
  </joint>
</robot>